<?xml version="1.0" ?>
<robot name="i2rt_yam">
   <!--generated with mjcf_urdf_simple_converter (https://github.com/Yasu31/mjcf_urdf_simple_converter)-->
   <!-- Further modified by https://github.com/stonet2000 to be simulation ready / maniskill compatible -->
   <link name="arm">
      <inertial>
         <origin xyz="0.0 0.0 0.026" rpy="0.0 0.0 0.0"/>
         <mass value="0.21895644158459424"/>
         <inertia ixx="0.00013879124248906134" iyy="0.00013879124248906134" izz="0.00010282878735692499" ixy="0" ixz="0" iyz="0"/>
      </inertial>
      <visual name="arm_visual">
         <!-- z-value was originally 0.01154286287615687 -->
         <origin xyz="-2.0738360577213484e-05 2.041311002275178e-05 0.023085726" rpy="1.5701130102263443 0.005344186766800929 -3.1414365496107033"/>
         <geometry>
            <mesh filename="meshes/arm.obj"/>
         </geometry>
      </visual>
      <collision name="arm_collision">
         <origin xyz="-2.0738360577213484e-05 2.041311002275178e-05 0.023085726" rpy="0 0.005344186766800929 -3.1414365496107033"/>
         <geometry>
            <cylinder radius="0.033" length="0.097728589"/>
         </geometry>
      </collision>
   </link>
   <link name="link_1">
      <inertial>
         <origin xyz="-0.00192861 -0.00795735 0.0208176" rpy="1.6743480392523336 -0.6015439689011489 1.5666873963753192"/>
         <mass value="0.12415"/>
         <inertia ixx="0.000180751" iyy="0.000145532" izz="5.89179e-05" ixy="0" ixz="0" iyz="0"/>
      </inertial>
      <visual name="link_1_visual">
         <origin xyz="0.0007117901440024366 -0.008267794027987337 0.022250179687008112" rpy="1.5650454550240567 -0.6317582807873866 1.5710673633815686"/>
         <geometry>
            <mesh filename="meshes/link_1.obj"/>
         </geometry>
      </visual>
      <collision name="link_1_collision">
         <origin xyz="0.0007117901440024366 -0.008267794027987337 0.022250179687008112" rpy="1.5650454550240567 -0.6317582807873866 1.5710673633815686"/>
         <geometry>
            <mesh filename="meshes/link_1.obj"/>
         </geometry>
      </collision>
   </link>
   <joint type="revolute" name="joint1">
      <parent link="arm"/>
      <child link="link_1"/>
      <origin xyz="0.0 0.0 0.074642863" rpy="0.0 0.0 1.5707963267948963"/>
      <axis xyz="0.0 0.0 1.0"/>
      <limit lower="-2.61799" upper="3.05433" effort="100" velocity="100"/>
   </joint>
   <link name="link_2">
      <inertial>
         <origin xyz="0.132008 2.10599e-06 0.000293073" rpy="1.5707963267948966 0.0 1.5707963267948966"/>
         <mass value="1.24434"/>
         <inertia ixx="0.0121902" iyy="0.0121318" izz="0.000683304" ixy="0" ixz="0" iyz="0"/>
      </inertial>
      <visual name="link_2_visual_1">
         <origin xyz="0.26007948449650414 2.5977632368834325e-07 0.00022869283697025413" rpy="0.0012886015838013964 0.0 1.5707963267948966"/>
         <geometry>
            <mesh filename="meshes/link_2_1.obj"/>
         </geometry>
      </visual>
      <visual name="link_2_visual_2">
         <origin xyz="0.003920561027152974 2.5977629421192194e-07 0.00022869282878015162" rpy="-0.0012886020855807923 0.0 1.5707963267948966"/>
         <geometry>
            <mesh filename="meshes/link_2_2.obj"/>
         </geometry>
      </visual>
      <visual name="link_2_visual_3">
         <origin xyz="0.1320117461361114 -1.306943646950387e-05 9.079293692478702e-08" rpy="1.5720341600620278 -1.5679213575591913 -1.5720413321414013"/>
         <geometry>
            <mesh filename="meshes/link_2_3.obj"/>
         </geometry>
      </visual>
      <collision name="link_2_collision_1">
         <origin xyz="0.26007948449650414 2.5977632368834325e-07 0.00022869283697025413" rpy="0.0012886015838013964 0.0 1.5707963267948966"/>
         <geometry>
            <mesh filename="meshes/link_2_1.obj"/>
         </geometry>
      </collision>
      <collision name="link_2_collision_2">
         <origin xyz="0.003920561027152974 2.5977629421192194e-07 0.00022869282878015162" rpy="-0.0012886020855807923 0.0 1.5707963267948966"/>
         <geometry>
            <mesh filename="meshes/link_2_2.obj"/>
         </geometry>
      </collision>
      <collision name="link_2_collision_3">
         <origin xyz="0.1320117461361114 -1.306943646950387e-05 9.079293692478702e-08" rpy="1.5720341600620278 -1.5679213575591913 -1.5720413321414013"/>
         <geometry>
            <mesh filename="meshes/link_2_3.obj"/>
         </geometry>
      </collision>
   </link>
   <joint type="revolute" name="joint2">
      <parent link="link_1"/>
      <child link="link_2"/>
      <origin xyz="2.5e-05 -0.02 0.0409" rpy="1.5707963267948966 0.0 1.5707963267948966"/>
      <axis xyz="0.0 0.0 1.0"/>
      <limit lower="0.0" upper="3.66519" effort="100" velocity="100"/>
   </joint>
   <link name="link_3">
      <inertial>
         <origin xyz="-0.121816 -0.054846 -0.000111108" rpy="1.5707963267948966 0.0 1.5707963267948966"/>
         <mass value="0.853698"/>
         <inertia ixx="0.00699732" iyy="0.00696112" izz="0.000788244" ixy="0" ixz="0" iyz="0"/>
      </inertial>
      <visual name="link_3_visual_1">
         <origin xyz="-0.24063976713274154 -0.059999782142154706 -0.003760273578300405" rpy="3.0364915071378875 0.0 -1.570796326794897"/>
         <geometry>
            <mesh filename="meshes/link_3_1.obj"/>
         </geometry>
      </visual>
      <visual name="link_3_visual_2">
         <origin xyz="-0.007710009148021196 -0.03486048010433765 0.0347071645682882" rpy="-2.8787900674372295 1.4720957652931412 1.6013719605643308"/>
         <geometry>
            <mesh filename="meshes/link_3_2.obj"/>
         </geometry>
      </visual>
      <visual name="link_3_visual_3">
         <origin xyz="-0.1206720859561709 -0.06001334031535149 5.408345552423209e-07" rpy="1.5707945314613085 0.0026832997041226214 -1.570809065297576"/>
         <geometry>
            <mesh filename="meshes/link_3_3.obj"/>
         </geometry>
      </visual>
      <visual name="link_3_visual_4">
         <origin xyz="-0.008240431625057998 -0.03737256683266851 -0.033699619180835645" rpy="0.2883614312261503 1.443690062944694 -1.515041718980295"/>
         <geometry>
            <mesh filename="meshes/link_3_4.obj"/>
         </geometry>
      </visual>
      <collision name="link_3_collision_1">
         <origin xyz="-0.24063976713274154 -0.059999782142154706 -0.003760273578300405" rpy="3.0364915071378875 0.0 -1.570796326794897"/>
         <geometry>
            <mesh filename="meshes/link_3_1.obj"/>
         </geometry>
      </collision>
      <collision name="link_3_collision_2">
         <origin xyz="-0.007710009148021196 -0.03486048010433765 0.0347071645682882" rpy="-2.8787900674372295 1.4720957652931412 1.6013719605643308"/>
         <geometry>
            <mesh filename="meshes/link_3_2.obj"/>
         </geometry>
      </collision>
      <collision name="link_3_collision_3">
         <origin xyz="-0.1206720859561709 -0.06001334031535149 5.408345552423209e-07" rpy="1.5707945314613085 0.0026832997041226214 -1.570809065297576"/>
         <geometry>
            <mesh filename="meshes/link_3_3.obj"/>
         </geometry>
      </collision>
      <collision name="link_3_collision_4">
         <origin xyz="-0.008240431625057998 -0.03737256683266851 -0.033699619180835645" rpy="0.2883614312261503 1.443690062944694 -1.515041718980295"/>
         <geometry>
            <mesh filename="meshes/link_3_4.obj"/>
         </geometry>
      </collision>
   </link>
   <joint type="revolute" name="joint3">
      <parent link="link_2"/>
      <child link="link_3"/>
      <origin xyz="0.264 0.0 0.0" rpy="3.141592653589793 0.0 0.0"/>
      <axis xyz="0.0 0.0 1.0"/>
      <limit lower="0.0" upper="3.66519" effort="100" velocity="100"/>
   </joint>
   <link name="link_4">
      <inertial>
         <origin xyz="-0.0769778 -0.0527104 0.000154878" rpy="1.5707963267948966 0.0 -0.6801532411309218"/>
         <mass value="0.463511"/>
         <inertia ixx="0.000791532" iyy="0.000744733" izz="0.000282116" ixy="0" ixz="0" iyz="0"/>
      </inertial>
      <visual name="link_4_visual">
         <origin xyz="-0.046776068687813616 -0.038270471745625256 -0.0008915243508352188" rpy="1.5394854457020646 0.021662003917253037 -0.7117475435376934"/>
         <geometry>
            <mesh filename="meshes/link_4.obj"/>
         </geometry>
      </visual>
      <collision name="link_4_collision">
         <origin xyz="-0.073 -0.067 0.0" rpy="1.5707963267948966 0.0 0.0"/>
         <geometry>
            <cylinder radius="0.03" length="0.05"/>
         </geometry>
      </collision>
   </link>
   <joint type="revolute" name="joint4">
      <parent link="link_3"/>
      <child link="link_4"/>
      <origin xyz="-0.245 -0.06 0.0" rpy="0.0 0.0 0.0"/>
      <axis xyz="0.0 0.0 1.0"/>
      <limit lower="-1.5708" upper="1.5708" effort="100" velocity="100"/>
   </joint>
   <link name="link_5">
      <inertial>
         <origin xyz="3.64861e-05 0.00025665 0.0353526" rpy="0.0 0.0 0.0"/>
         <mass value="0.350962"/>
         <inertia ixx="0.000197802" iyy="0.0001775" izz="0.000147402" ixy="0" ixz="0" iyz="0"/>
      </inertial>
      <visual name="link_5_visual">
         <origin xyz="5.815639855540116e-05 -0.0005553836621680353 0.03206235288381598" rpy="2.67318045036048 0.0016544870659682687 -0.011529382184967352"/>
         <geometry>
            <mesh filename="meshes/link_5.obj"/>
         </geometry>
      </visual>
      <collision name="link_5_collision">
         <origin xyz="0.0 0.0 0.0395" rpy="1.5707963267948966 0.0 0.0"/>
         <geometry>
            <cylinder radius="0.03" length="0.05"/>
         </geometry>
      </collision>
   </link>
   <joint type="revolute" name="joint5">
      <parent link="link_4"/>
      <child link="link_5"/>
      <origin xyz="-0.074 -0.0395 2.5e-05" rpy="-1.5707963267948966 1.5707963267948966 0.0"/>
      <axis xyz="0.0 0.0 1.0"/>
      <limit lower="-1.5708" upper="1.5708" effort="100" velocity="100"/>
   </joint>
   <link name="link_6">
      <inertial>
         <origin xyz="-0.000217767 7.37059e-05 0.0270545" rpy="1.5707963267948963 0.0 0.0"/>
         <mass value="0.367476"/>
         <inertia ixx="0.000265958" iyy="0.000242686" izz="0.000227409" ixy="0" ixz="0" iyz="0"/>
      </inertial>
      <visual name="link_6_visual">
         <origin xyz="8.788302043375991e-05 0.0001190912220788709 0.05116721790419726" rpy="-1.745366888758472 1.5654909718508199 -1.969912540567698"/>
         <geometry>
            <mesh filename="meshes/link_6_1.obj"/>
         </geometry>
      </visual>
      <visual name="link_6_visual">
         <origin xyz="-0.00017825474995774047 1.6195054943213272e-05 0.03422382038141725" rpy="-1.5799559470247644 0.8170286688385331 -0.14641337505452368"/>
         <geometry>
            <mesh filename="meshes/link_6_2.obj"/>
         </geometry>
      </visual>
      <collision name="link_6_collision">
         <!-- <origin xyz="8.788302043375991e-05 0.0001190912220788709 0.05116721790419726" rpy="-1.745366888758472 1.5654909718508199 -1.969912540567698"/>
         <geometry>
            <mesh filename="meshes/converted_model2__12_404040ff.obj"/>
         </geometry> -->
         <origin xyz="0.0 0.0 0.017" rpy="0 0.0 0.0"/>
         <geometry>
            <cylinder radius="0.03" length="0.055"/>
         </geometry>
      </collision>
      <!-- this is internal -->
      <!-- <collision name="link_6_collision">
         <origin xyz="-0.00017825474995774047 1.6195054943213272e-05 0.03422382038141725" rpy="-1.5799559470247644 0.8170286688385331 -0.14641337505452368"/>
         <geometry>
            <mesh filename="meshes/converted_model2__13_404040ff.obj"/>
         </geometry>
      </collision> -->
   </link>
   <joint type="revolute" name="joint6">
      <parent link="link_5"/>
      <child link="link_6"/>
      <origin xyz="0.0 0.0353 0.0395" rpy="-1.5707963267948957 0.0 0.0"/>
      <axis xyz="0.0 0.0 1.0"/>
      <limit lower="-2.0944" upper="2.0944" effort="100" velocity="100"/>
   </joint>
   <link name="link_left_finger">
      <inertial>
         <origin xyz="-0.0192995 -0.0365902 0.039774" rpy="1.401155911297378 -0.506095322833723 -0.42940521230428"/>
         <mass value="0.118"/>
         <inertia ixx="0.000159084" iyy="0.000154909" izz="4.63655e-05" ixy="0" ixz="0" iyz="0"/>
      </inertial>
      <visual name="link_left_finger_visual_1">
         <origin xyz="-0.02621919095860112 -0.050961301789609365 0.04847966761952425" rpy="1.2436149090470108 -1.3351755324428625 3.1192068678405445"/>
         <geometry>
            <mesh filename="meshes/link_left_finger_1.obj"/>
         </geometry>
      </visual>
      <visual name="link_left_finger_visual_2">
         <origin xyz="-0.0018267628293356375 -0.014013453565219658 0.02860778296204746" rpy="-0.08499655397451025 -0.08210615684708134 0.012014286826329143"/>
         <geometry>
            <mesh filename="meshes/link_left_finger_2.obj"/>
         </geometry>
      </visual>
      <collision name="link_left_finger_collision_1">
         <origin xyz="-0.02621919095860112 -0.050961301789609365 0.04847966761952425" rpy="1.2436149090470108 -1.3351755324428625 3.1192068678405445"/>
         <geometry>
            <mesh filename="meshes/link_left_finger_1.obj"/>
         </geometry>
      </collision>
      <collision name="link_left_finger_collision_2">
         <origin xyz="-0.0018267628293356375 -0.014013453565219658 0.02860778296204746" rpy="-0.08499655397451025 -0.08210615684708134 0.012014286826329143"/>
         <geometry>
            <mesh filename="meshes/link_left_finger_2.obj"/>
         </geometry>
      </collision>
   </link>
   <joint type="prismatic" name="left_finger">
      <parent link="link_6"/>
      <child link="link_left_finger"/>
      <origin xyz="-0.037 0.0392 0.0605" rpy="-0.0 1.5707963267948966 0.0"/>
      <axis xyz="0 0 1"/>
      <limit lower="0.0" upper="0.041" />
   </joint>
   <link name="link_right_finger">
      <inertial>
         <origin xyz="-0.0192995 0.0365902 -0.039774" rpy="-1.401155911297378 0.506095322833723 -0.42940521230428"/>
         <mass value="0.118"/>
         <inertia ixx="0.000159084" iyy="0.000154909" izz="4.63655e-05" ixy="0" ixz="0" iyz="0"/>
      </inertial>
      <visual name="link_right_finger_visual_1">
         <origin xyz="-0.001826763203738313 0.014013021507929144 -0.02860778467768097" rpy="-0.08499624911644796 0.08210615585822456 -0.012014239544932075"/>
         <geometry>
            <mesh filename="meshes/link_right_finger_1.obj"/>
         </geometry>
      </visual>
      <visual name="link_right_finger_visual_2">
         <origin xyz="-0.026152342123741346 0.026813733867866105 -0.04844908896546901" rpy="-1.8906094630983064 -1.3387155199773018 -0.013733131456833414"/>
         <geometry>
            <mesh filename="meshes/link_right_finger_2.obj"/>
         </geometry>
      </visual>
      <collision name="link_right_finger_collision_1">
         <origin xyz="-0.001826763203738313 0.014013021507929144 -0.02860778467768097" rpy="-0.08499624911644796 0.08210615585822456 -0.012014239544932075"/>
         <geometry>
            <mesh filename="meshes/link_right_finger_1.obj"/>
         </geometry>
      </collision>
      <collision name="link_right_finger_collision_2">
         <origin xyz="-0.026152342123741346 0.026813733867866105 -0.04844908896546901" rpy="-1.8906094630983064 -1.3387155199773018 -0.013733131456833414"/>
         <geometry>
            <mesh filename="meshes/link_right_finger_2.obj"/>
         </geometry>
      </collision>
   </link>
   <joint type="prismatic" name="right_finger">
      <parent link="link_6"/>
      <child link="link_right_finger"/>
      <origin xyz="0.037 -0.0392 0.0605" rpy="-0.0 1.5707963267948966 0.0"/>
      <axis xyz="0 0 -1"/>
      <limit lower="0.0" upper="0.041" />
      <mimic joint="left_finger"/>
   </joint>
</robot>
